Workbook

Sheet Vårt 2025
B3: Boliger | C3: Forbruk GWh | D3: Metode | E3: Forbruk / enhet | F3: Antall enheter | G3: Kilde
B4: Elektrisitet | D4: Forbruk pr husholdning * antall husholdninger | E4: 15000 | F4: 2649395 | G4: Familier og husholdninger – SSB
B5: Elektrisitet | C5: =+E5*F5/1000000 -> 38333.55 | D5: Forbruk pr person * antall personer | E5: 6900 | F5: 5555587
B6: Fjernvarme | C6: 2000 | D6: Trendframskriving
B7: Bio | C7: =+E7*F7/1000000 -> 4875 | D7: Innfyrt energi pr husholdning med vedovn * antall husholdninger med vedovn | E7: 3900 | F7: 1250000
B8: Varmepumper | C8: =+VP!$H$25 -> 13490.195 | D8: Ingrids modell, produsert varme
B10: Yrkesbygg | C10: Forbruk GWh | D10: Metode | E10: Forbruk / enhet | F10: Antall enheter | G10: Kilde
B11: Elektrisitet | C11: =+E11*F11/1000000 -> 23889.024 | D11: Forbruk pr person * befolkning | E11: 4300 | F11: =+F5 -> 5555587
B12: Fjernvarme | C12: 4200 | D12: Trendframskriving
B13: Varmepumper | C13: 7000 | D13: Ingrids modell, produsert varme
C15: LEVERT ENERGI | E15: 2005 | F15: 2006 | G15: 2007 | H15: 2008 | I15: 2009 | J15: 2010 | K15: 2011 | L15: 2012 | M15: 2013 | N15: 2014 | O15: 2015 | P15: 2016 | Q15: 2017 | R15: 2018 | S15: 2019 | T15: 2020 | U15: 2021 | V15: 2022 | W15: 2023 | X15: 2024 | Y15: 2025
C16: Bolig | D16: Elektrisitet uten VP tempkorr | E16: =+Elektrisitet!B22-'Vårt 2025'!E17 -> 32679.062 | F16: =+Elektrisitet!C22-'Vårt 2025'!F17 -> 32404.971 | G16: =+Elektrisitet!D22-'Vårt 2025'!G17 -> 32544.153 | H16: =+Elektrisitet!E22-'Vårt 2025'!H17 -> 32287.731 | I16: =+Elektrisitet!F22-'Vårt 2025'!I17 -> 32319.362 | J16: =+Elektrisitet!G22-'Vårt 2025'!J17 -> 31768.154 | K16: =+Elektrisitet!H22-'Vårt 2025'!K17 -> 32519.171 | L16: =+Elektrisitet!I22-'Vårt 2025'!L17 -> 32312.353 | ... X16: =+Elektrisitet!U22-'Vårt 2025'!X17 -> 32266.985 | Y16: =+C5-Y17 -> 31821.61
C17: Bolig | D17: Elektristet til VP | E17: 789.69484 | F17: 1141.4859 | G17: 1460.3942 | H17: 1836.3567 | I17: 2200.2665 | J17: 2608.0766 | K17: 2975.1721 | L17: 3240.1166 | M17: 3465.6158 | N17: 3646.1504 | O17: 3836.3567 | P17: 4034.4967 | Q17: 4231.0051 | R17: 4489.4945 | S17: 4744.464 | T17: 4910.6799 | U17: 5205.0857 | V17: 5599.2792 | W17: 5981.6196 | X17: 6276.8924 | Y17: 6511.9399 | Z17: VP modellen
C18: Bolig | D18: =+D34 -> Fjernvarme tempkorr | E18: 439.74443 | F18: 528.53623 | G18: 579.02041 | H18: 740.86859 | I18: 746.1889 | J18: 946.1266 | K18: 828.48403 | L18: 921.82416 | M18: 1071.2213 | N18: 1105.3603 | O18: 1107.7001 | P18: 1247.6687 | Q18: 1395.4228 | R18: 1442.1821 | S18: 1587.3965 | T18: 1644.0131 | U18: 1732.0248 | V18: 1759.1349 | W18: 1926.5466 | X18: 1984.0182 | Y18: =+C6 -> 2000
C19: Bolig | D19: Bio levert/innfyrt energi tempkorr | E19: =+Bio!C9*1000 -> 6680.2639 | F19: =+Bio!D9*1000 -> 6822.8882 | G19: =+Bio!E9*1000 -> 6217.2137 | H19: =+Bio!F9*1000 -> 6238.878 | I19: =+Bio!G9*1000 -> 6160.2715 | J19: =+Bio!H9*1000 -> 5845.0414 | K19: =+Bio!I9*1000 -> 6576.8771 | L19: =+Bio!J9*1000 -> 6567.1589 | ... X19: =+Bio!V9*1000 -> 4869.4889 | Y19: =+C7 -> 4875
C20: Yrkesbygg | D20: Elektrisitet uten VP tempkorr | O20: =+Elektrisitet!L33-'Vårt 2025'!O21 -> 23258.134 | P20: =+Elektrisitet!M33-'Vårt 2025'!P21 -> 23311.351 | Q20: =+Elektrisitet!N33-'Vårt 2025'!Q21 -> 23054.383 | R20: =+Elektrisitet!O33-'Vårt 2025'!R21 -> 23464.413 | S20: =+Elektrisitet!P33-'Vårt 2025'!S21 -> 22989.529 | T20: =+Elektrisitet!Q33-'Vårt 2025'!T21 -> 23280.242 | U20: =+Elektrisitet!R33-'Vårt 2025'!U21 -> 23210.958 | V20: =+Elektrisitet!S33-'Vårt 2025'!V21 -> 21563.772 | ... X20: =+Elektrisitet!U33-'Vårt 2025'!X21 -> 20724.078 | Y20: =+C11-Y21 -> 21184.276
C21: Yrkesbygg | D21: Elektristet til VP | F21: 581.46042 | G21: 709.01289 | H21: 862.71503 | I21: 1010.9029 | J21: 1166.7809 | K21: 1322.9226 | L21: 1444.2248 | M21: 1554.495 | N21: 1657.2265 | O21: 1755.4265 | P21: 1855.4306 | Q21: 1961.7273 | R21: 2097.5452 | S21: 2204.7121 | T21: 2262.1039 | U21: 2338.9721 | V21: 2455.364 | W21: 2587.1852 | X21: 2653 | Y21: 2704.7482 | Z21: VP modellen
C22: Yrkesbygg | D22: =+D38 -> Fjernvarme tempkorr | F22: =+F38 -> 1934.6823 | G22: =+G38 -> 2057.7216 | H22: =+H38 -> 2091.8132 | I22: =+I38 -> 2328.4076 | J22: =+J38 -> 2565.2707 | K22: =+K38 -> 2876.3436 | L22: =+L38 -> 2904.7265 | M22: =+M38 -> 3213.9851 | ... W22: =+W38 -> 3999.5489 | X22: 4113.4687 | Y22: =+C12 -> 4200
D24: Bolig | O24: =+SUM(O16:O19) -> 44107.578 | P24: =+SUM(P16:P19) -> 43998.488 | Q24: =+SUM(Q16:Q19) -> 44527.025 | R24: =+SUM(R16:R19) -> 44549.827 | S24: =+SUM(S16:S19) -> 43929.154 | T24: =+SUM(T16:T19) -> 47282.091 | U24: =+SUM(U16:U19) -> 45951.859 | V24: =+SUM(V16:V19) -> 42963.504 | ... Y24: =+SUM(Y16:Y19) -> 45208.55
D25: Yrkesbygg | O25: =+SUM(O20:O22) -> 28389.856 | P25: =+SUM(P20:P22) -> 28649.549 | Q25: =+SUM(Q20:Q22) -> 28431.489 | R25: =+SUM(R20:R22) -> 29216.432 | S25: =+SUM(S20:S22) -> 28848.64 | T25: =+SUM(T20:T22) -> 29019.228 | U25: =+SUM(U20:U22) -> 29400.627 | V25: =+SUM(V20:V22) -> 27853.623 | ... Y25: =+SUM(Y20:Y22) -> 28089.024
D26: Totalt | O26: =+SUM(O16:O22) -> 72497.434 | P26: =+SUM(P16:P22) -> 72648.037 | Q26: =+SUM(Q16:Q22) -> 72958.514 | R26: =+SUM(R16:R22) -> 73766.258 | S26: =+SUM(S16:S22) -> 72777.794 | T26: =+SUM(T16:T22) -> 76301.318 | U26: =+SUM(U16:U22) -> 75352.486 | V26: =+SUM(V16:V22) -> 70817.127 | ... Y26: =+SUM(Y16:Y22) -> 73297.574
D28: Strøm | O28: =+O16+O17+O20+O21 -> 63238.462 | P28: =+P16+P17+P20+P21 -> 63521.624 | Q28: =+Q16+Q17+Q20+Q21 -> 63399.001 | R28: =+R16+R17+R20+R21 -> 64208.203 | S28: =+S16+S17+S20+S21 -> 63501.612 | T28: =+T16+T17+T20+T21 -> 66462.024 | U28: =+U16+U17+U20+U21 -> 64822.683 | V28: =+V16+V17+V20+V21 -> 59623.591 | ... Y28: =+Y16+Y17+Y20+Y21 -> 62222.574
D29: Fjernvarme | O29: =+O18+O22 -> 4483.9955 | P29: =+P18+P22 -> 4730.4359 | Q29: =+Q18+Q22 -> 4810.8014 | R29: =+R18+R22 -> 5096.6556 | S29: =+S18+S22 -> 5241.795 | T29: =+T18+T22 -> 5120.8954 | U29: =+U18+U22 -> 5582.722 | V29: =+V18+V22 -> 5593.6218 | ... Y29: =+Y18+Y22 -> 6200
D30: Ved | O30: =+O19 -> 4774.9764 | P30: =+P19 -> 4395.9768 | Q30: =+Q19 -> 4748.712 | R30: =+R19 -> 4461.3996 | S30: =+S19 -> 4034.3865 | T30: =+T19 -> 4718.3995 | U30: =+U19 -> 4947.0815 | V30: =+V19 -> 5599.9142 | ... Y30: =+Y19 -> 4875
C33: NYTTIGGJORT ENERGI | E33: 2005 | F33: 2006 | G33: 2007 | H33: 2008 | I33: 2009 | J33: 2010 | K33: 2011 | L33: 2012 | M33: 2013 | N33: 2014 | O33: 2015 | P33: 2016 | Q33: 2017 | R33: 2018 | S33: 2019 | T33: 2020 | U33: 2021 | V33: 2022 | W33: 2023 | X33: 2024 | Y33: 2025
C34: Bolig | D34: Fjernvarme tempkorr | F34: 528.53623 | G34: 579.02041 | H34: 740.86859 | I34: 746.1889 | J34: 946.1266 | K34: 828.48403 | L34: 921.82416 | M34: 1071.2213 | N34: 1105.3603 | O34: 1107.7001 | P34: 1247.6687 | Q34: 1395.4228 | R34: 1442.1821 | S34: 1587.3965 | T34: 1644.0131 | U34: 1732.0248 | V34: 1759.1349 | W34: 1926.5466 | X34: =+V34*$E$2*#REF!/W34+V34*(1-$E$2) -> #REF! | Y34: =+C6 -> 2000
C35: Bolig | D35: Bio produsert varme tempkorr | F35: =+Bio!D34 -> 5795.9584 | G35: =+Bio!E34 -> 5297.8586 | H35: =+Bio!F34 -> 5357.3019 | I35: =+Bio!G34 -> 5213.4938 | J35: =+Bio!H34 -> 4736.1287 | K35: =+Bio!I34 -> 5268.7482 | L35: =+Bio!J34 -> 0 | M35: =+Bio!K34 -> 4160.9769 | ... X35: =+Bio!V34 -> 3788.1363
C36: Bolig | D36: Varmepumper produsert varme | F36: 2384.7072 | G36: 3046.0957 | H36: 3827.8027 | I36: 4584.7116 | J36: 5426.14 | K36: 6189.16 | L36: 6743.8887 | M36: 7217.4555 | N36: 7600.398 | O36: 7999.0711 | P36: 8413.4735 | Q36: 8823.8787 | R36: 9368.1737 | S36: 9897.4009 | T36: 10237.884 | U36: 10834.189 | V36: 11636.35 | W36: 12421.077 | X36: =+C8 -> 13490.195
C37: Yrkesbygg | D37: Elektrisitet uten VP tempkorr
C38: Yrkesbygg | D38: Fjernvarme tempkorr | F38: 1934.6823 | G38: 2057.7216 | H38: 2091.8132 | I38: 2328.4076 | J38: 2565.2707 | K38: 2876.3436 | L38: 2904.7265 | M38: 3213.9851 | N38: 3383.5847 | O38: 3376.2954 | P38: 3482.7673 | Q38: 3415.3786 | R38: 3654.4735 | S38: 3654.3985 | T38: 3476.8823 | U38: 3850.6971 | V38: 3834.4869 | W38: 3999.5489 | X38: =+C12 -> 4200
C39: Yrkesbygg | D39: Varmepumper produsert varme | F39: 1498.9603 | G39: 1827.6491 | H39: 2228.4377 | I39: 2615.7391 | J39: 3008.4052 | K39: 3413.0929 | L39: 3735.1276 | M39: 4027.688 | N39: 4303.0046 | O39: 4557.1488 | P39: 4814.9291 | Q39: 5082.9531 | R39: 5441.1802 | S39: 5718.0165 | T39: 5859.3236 | U39: 6038.1366 | V39: 6316.0039 | W39: 6645.9532 | X39: =+C13 -> 7000
D40: Boliger | F40: =+SUM(F34:F36) -> 8709.2018 | G40: =+SUM(G34:G36) -> 8922.9748 | H40: =+SUM(H34:H36) -> 9925.9732 | I40: =+SUM(I34:I36) -> 10544.394 | J40: =+SUM(J34:J36) -> 11108.395 | K40: =+SUM(K34:K36) -> 12286.392 | L40: =+SUM(L34:L36) -> 7665.7129 | M40: =+SUM(M34:M36) -> 12449.654 | ... X40: =+SUM(X34:X36) -> #REF!
D41: Yrkesbygg | F41: =+SUM(F37:F39) -> 3433.6426 | G41: =+SUM(G37:G39) -> 3885.3707 | H41: =+SUM(H37:H39) -> 4320.2509 | I41: =+SUM(I37:I39) -> 4944.1467 | J41: =+SUM(J37:J39) -> 5573.6759 | K41: =+SUM(K37:K39) -> 6289.4365 | L41: =+SUM(L37:L39) -> 6639.8541 | M41: =+SUM(M37:M39) -> 7241.6731 | ... X41: =+SUM(X37:X39) -> 11200
D42: Totalt | F42: =+SUM(F34:F39) -> 12142.844 | G42: =+SUM(G34:G39) -> 12808.345 | H42: =+SUM(H34:H39) -> 14246.224 | I42: =+SUM(I34:I39) -> 15488.541 | J42: =+SUM(J34:J39) -> 16682.071 | K42: =+SUM(K34:K39) -> 18575.829 | L42: =+SUM(L34:L39) -> 14305.567 | M42: =+SUM(M34:M39) -> 19691.327 | ... X42: =+SUM(X34:X39) -> #REF!

Sheet Elektrisitet
A1: 13929: Energiforbruk i husholdninger og fritidshus, etter statistikkvariabel og år
B3: 2005 | C3: 2006 | D3: 2007 | E3: 2008 | F3: 2009 | G3: 2010 | H3: 2011 | I3: 2012 | J3: 2013 | K3: 2014 | L3: 2015 | M3: 2016 | N3: 2017 | O3: 2018 | P3: 2019 | Q3: 2020 | R3: 2021 | S3: 2022 | T3: 2023 | U3: 2024
A4: Historisk graddagstall | B4: 3734 | C4: 3734 | D4: 3734 | E4: 3734 | F4: 3734 | G4: 3734 | H4: 3734 | I4: 3734 | J4: 3734 | K4: 3734 | L4: 3734 | M4: 3734 | N4: 3734 | O4: 3734 | P4: 3734 | Q4: 3734 | R4: 3734 | S4: 3734 | T4: 3734 | U4: 3734
A5: Observerte graddager | B5: 3599.3523 | C5: 3502.2232 | D5: 3645.2306 | E5: 3590.6813 | F5: 3763.7768 | G5: 4439.4516 | H5: 3508.3334 | I5: 3877.3853 | J5: 3785.0953 | K5: 3299.1393 | L5: 3440.4366 | M5: 3601.1612 | N5: 3632.3086 | O5: 3623.672 | P5: 3618.5232 | Q5: 3244.3019 | R5: 3690.5569 | S5: 3453.6672 | T5: 3730 | U5: 3434.6998
A7: Elektrisitet i boliger, unntatt lading av elbiler (GWh) | B7: 32770 | C7: 32327 | D7: 33539 | E7: 33365 | F7: 34676 | G7: 37800 | H7: 34239 | I7: 36318 | J7: 36761 | K7: 34865 | L7: 36452 | M7: 37565 | N7: 37780 | O7: 37987 | P7: 37623 | Q7: 37678 | R7: 39011 | S7: 34030 | T7: 36418 | U7: =38370-1650 -> 36720
A8: Elektrisitet i boliger, unntatt lading av elbiler (GWh), temperaturkorrigert | B8: =B7*($B$17*(B4/B5)+(1-$B$17)) -> 33468.757 | C8: =C7*($B$17*(C4/C5)+(1-$B$17)) -> 33546.457 | D8: =D7*($B$17*(D4/D5)+(1-$B$17)) -> 34004.547 | E8: =E7*($B$17*(E4/E5)+(1-$B$17)) -> 34124.088 | F8: =F7*($B$17*(F4/F5)+(1-$B$17)) -> 34519.629 | G8: =G7*($B$17*(G4/G5)+(1-$B$17)) -> 34376.23 | H8: =H7*($B$17*(H4/H5)+(1-$B$17)) -> 35494.343 | I8: =I7*($B$17*(I4/I5)+(1-$B$17)) -> 35552.47 | ... U8: =U7*($B$17*(U4/U5)+(1-$B$17)) -> 38543.878
A9: Folkemengde per 1. januar | B9: 4606363 | C9: 4640219 | D9: 4681134 | E9: 4737171 | F9: 4799252 | G9: 4858199 | H9: 4920305 | I9: 4985870 | J9: 5051275 | K9: 5109056 | L9: 5165802 | M9: 5213985 | N9: 5258317 | O9: 5295619 | P9: 5328212 | Q9: 5367580 | R9: 5391369 | S9: 5425270 | T9: 5488984 | U9: 5539416
A10: Antall husholdninger per 1. januar | B10: 2010999 | C10: 2036890 | D10: 2064841 | E10: 2104531 | F10: 2142638 | G10: 2170893 | H10: 2201787 | I10: 2226046 | J10: 2258794 | K10: 2286445 | L10: 2316647 | M10: 2348797 | N10: 2376971 | O10: 2409257 | P10: 2439242 | Q10: 2475168 | R10: 2512317 | S10: 2545902 | T10: 2581721 | U10: 2617268
A12: Per person kWh | B12: =(B7*1000*1000)/B9 -> 7114.0724 | C12: =(C7*1000*1000)/C9 -> 6966.697 | D12: =(D7*1000*1000)/D9 -> 7164.7169 | E12: =(E7*1000*1000)/E9 -> 7043.2332 | F12: =(F7*1000*1000)/F9 -> 7225.2926 | G12: =(G7*1000*1000)/G9 -> 7780.6611 | H12: =(H7*1000*1000)/H9 -> 6958.715 | I12: =(I7*1000*1000)/I9 -> 7284.1851 | ... U12: =(U7*1000*1000)/U9 -> 6628.8576
A13: Per husholdning kWh | B13: =(B7*1000*1000)/B10 -> 16295.384 | C13: =(C7*1000*1000)/C10 -> 15870.764 | D13: =(D7*1000*1000)/D10 -> 16242.897 | E13: =(E7*1000*1000)/E10 -> 15853.889 | F13: =(F7*1000*1000)/F10 -> 16183.788 | G13: =(G7*1000*1000)/G10 -> 17412.189 | H13: =(H7*1000*1000)/H10 -> 15550.551 | I13: =(I7*1000*1000)/I10 -> 16315.027 | ... U13: =(U7*1000*1000)/U10 -> 14029.897
A14: Per person kWh, temperaturkorrigert | B14: =(B8*1000*1000)/B9 -> 7265.7662 | C14: =(C8*1000*1000)/C9 -> 7229.4985 | D14: =(D8*1000*1000)/D9 -> 7264.1687 | E14: =(E8*1000*1000)/E9 -> 7203.4739 | F14: =(F8*1000*1000)/F9 -> 7192.7101 | G14: =(G8*1000*1000)/G9 -> 7075.9206 | H14: =(H8*1000*1000)/H9 -> 7213.8501 | I14: =(I8*1000*1000)/I9 -> 7130.6452 | ... U14: =(U8*1000*1000)/U9 -> 6958.1121
A15: Per husholdning kWh, temperaturkorrigert | B15: =(B8*1000*1000)/B10 -> 16642.851 | C15: =(C8*1000*1000)/C10 -> 16469.449 | D15: =(D8*1000*1000)/D10 -> 16468.361 | E15: =(E8*1000*1000)/E10 -> 16214.581 | F15: =(F8*1000*1000)/F10 -> 16110.808 | G15: =(G8*1000*1000)/G10 -> 15835.064 | H15: =(H8*1000*1000)/H10 -> 16120.698 | I15: =(I8*1000*1000)/I10 -> 15971.13 | ... U15: =(U8*1000*1000)/U10 -> 14726.76
A17: HH andel temperaturkorrigert | B17: 0.57
A18: TJ andel temperaturkorrigert | B18: 0.32
A21: TEMPERATURKORRIGERT | B21: 2005 | C21: 2006 | D21: 2007 | E21: 2008 | F21: 2009 | G21: 2010 | H21: 2011 | I21: 2012 | J21: 2013 | K21: 2014 | L21: 2015 | M21: 2016 | N21: 2017 | O21: 2018 | P21: 2019 | Q21: 2020 | R21: 2021 | S21: 2022 | T21: 2023 | U21: 2024
A22: Elektrisitet i boliger | B22: =+B8 -> 33468.757 | C22: =+C8 -> 33546.457 | D22: =+D8 -> 34004.547 | E22: =+E8 -> 34124.088 | F22: =+F8 -> 34519.629 | G22: =+G8 -> 34376.23 | H22: =+H8 -> 35494.343 | I22: =+I8 -> 35552.47 | ... U22: =+U8 -> 38543.878
A23: Elektrisitet pr husholdning | B23: =+B22*1000000/B10 -> 16642.851 | C23: =+C22*1000000/C10 -> 16469.449 | D23: =+D22*1000000/D10 -> 16468.361 | E23: =+E22*1000000/E10 -> 16214.581 | F23: =+F22*1000000/F10 -> 16110.808 | G23: =+G22*1000000/G10 -> 15835.064 | H23: =+H22*1000000/H10 -> 16120.698 | I23: =+I22*1000000/I10 -> 15971.13 | ... U23: =+U22*1000000/U10 -> 14726.76
A24: Snitt 20 år (15 900 kWh) | B24: =+AVERAGE($B$23:$U$23) -> 15904.502 | C24: =+AVERAGE($B$23:$U$23) -> 15904.502 | D24: =+AVERAGE($B$23:$U$23) -> 15904.502 | E24: =+AVERAGE($B$23:$U$23) -> 15904.502 | F24: =+AVERAGE($B$23:$U$23) -> 15904.502 | G24: =+AVERAGE($B$23:$U$23) -> 15904.502 | H24: =+AVERAGE($B$23:$U$23) -> 15904.502 | I24: =+AVERAGE($B$23:$U$23) -> 15904.502 | ... U24: =+AVERAGE($B$23:$U$23) -> 15904.502
A25: Snitt 10 år (15 600) | K25: =+AVERAGE($K$23:$U$23) -> 15646.155 | L25: =+AVERAGE($K$23:$U$23) -> 15646.155 | M25: =+AVERAGE($K$23:$U$23) -> 15646.155 | N25: =+AVERAGE($K$23:$U$23) -> 15646.155 | O25: =+AVERAGE($K$23:$U$23) -> 15646.155 | P25: =+AVERAGE($K$23:$U$23) -> 15646.155 | Q25: =+AVERAGE($K$23:$U$23) -> 15646.155 | R25: =+AVERAGE($K$23:$U$23) -> 15646.155 | ... U25: =+AVERAGE($K$23:$U$23) -> 15646.155
A26: Snitt 5 år (15 100) | P26: =+AVERAGE($P$23:$U$23) -> 15115.878 | Q26: =+AVERAGE($P$23:$U$23) -> 15115.878 | R26: =+AVERAGE($P$23:$U$23) -> 15115.878 | S26: =+AVERAGE($P$23:$U$23) -> 15115.878 | T26: =+AVERAGE($P$23:$U$23) -> 15115.878 | U26: =+AVERAGE($P$23:$U$23) -> 15115.878
A27: Elektrisitet pr person | B27: =+B22*1000000/B9 -> 7265.7662 | C27: =+C22*1000000/C9 -> 7229.4985 | D27: =+D22*1000000/D9 -> 7264.1687 | E27: =+E22*1000000/E9 -> 7203.4739 | F27: =+F22*1000000/F9 -> 7192.7101 | G27: =+G22*1000000/G9 -> 7075.9206 | H27: =+H22*1000000/H9 -> 7213.8501 | I27: =+I22*1000000/I9 -> 7130.6452 | ... U27: =+U22*1000000/U9 -> 6958.1121
A28: Snitt 20 år (7 000 kWh) | B28: =+AVERAGE($B$27:$U$27) -> 7187.2241 | C28: =+AVERAGE($B$27:$U$27) -> 7187.2241 | D28: =+AVERAGE($B$27:$U$27) -> 7187.2241 | E28: =+AVERAGE($B$27:$U$27) -> 7187.2241 | F28: =+AVERAGE($B$27:$U$27) -> 7187.2241 | G28: =+AVERAGE($B$27:$U$27) -> 7187.2241 | H28: =+AVERAGE($B$27:$U$27) -> 7187.2241 | I28: =+AVERAGE($B$27:$U$27) -> 7187.2241 | ... U28: =+AVERAGE($B$27:$U$27) -> 7187.2241
A29: Snitt 10 år (6 900 kWh) | K29: =+AVERAGE($K$27:$U$27) -> 7176.9889 | L29: =+AVERAGE($K$27:$U$27) -> 7176.9889 | M29: =+AVERAGE($K$27:$U$27) -> 7176.9889 | N29: =+AVERAGE($K$27:$U$27) -> 7176.9889 | O29: =+AVERAGE($K$27:$U$27) -> 7176.9889 | P29: =+AVERAGE($K$27:$U$27) -> 7176.9889 | Q29: =+AVERAGE($K$27:$U$27) -> 7176.9889 | R29: =+AVERAGE($K$27:$U$27) -> 7176.9889 | ... U29: =+AVERAGE($K$27:$U$27) -> 7176.9889
A30: Snitt 5 år (6 800 kWh) | P30: =+AVERAGE($P$27:$U$27) -> 7042.8359 | Q30: =+AVERAGE($P$27:$U$27) -> 7042.8359 | R30: =+AVERAGE($P$27:$U$27) -> 7042.8359 | S30: =+AVERAGE($P$27:$U$27) -> 7042.8359 | T30: =+AVERAGE($P$27:$U$27) -> 7042.8359 | U30: =+AVERAGE($P$27:$U$27) -> 7042.8359
A32: Hentet fra 10 TWh-rapporten | B32: 2005 | C32: 2006 | D32: 2007 | E32: 2008 | F32: 2009 | G32: 2010 | H32: 2011 | I32: 2012 | J32: 2013 | K32: 2014 | L32: 2015 | M32: 2016 | N32: 2017 | O32: 2018 | P32: 2019 | Q32: 2020 | R32: 2021 | S32: 2022 | T32: 2023 | U32: 2024
A33: Elektrisitet i yrkesbygg | L33: 25013.561 | M33: 25166.782 | N33: 25016.111 | O33: 25561.958 | P33: 25194.241 | Q33: 25542.345 | R33: 25549.93 | S33: 24019.136 | T33: 22978.472 | U33: 23377.078 | V33: 23900
A34: Elektrisitet pr person | L34: =+L33/L9*1000000 -> 4842.1447 | M34: =+M33/M9*1000000 -> 4826.7845 | N34: =+N33/N9*1000000 -> 4757.4368 | O34: =+O33/O9*1000000 -> 4827.001 | P34: =+P33/P9*1000000 -> 4728.4608 | Q34: =+Q33/Q9*1000000 -> 4758.6334 | R34: =+R33/R9*1000000 -> 4739.0431 | S34: =+S33/S9*1000000 -> 4427.2702 | ... U34: =+U33/U9*1000000 -> 4220.1341
A35: Snitt 10 år (4 600 kWh) | L35: =+AVERAGE($L$34:$U$34) -> 4631.3197 | M35: =+AVERAGE($L$34:$U$34) -> 4631.3197 | N35: =+AVERAGE($L$34:$U$34) -> 4631.3197 | O35: =+AVERAGE($L$34:$U$34) -> 4631.3197 | P35: =+AVERAGE($L$34:$U$34) -> 4631.3197 | Q35: =+AVERAGE($L$34:$U$34) -> 4631.3197 | R35: =+AVERAGE($L$34:$U$34) -> 4631.3197 | S35: =+AVERAGE($L$34:$U$34) -> 4631.3197 | ... U35: =+AVERAGE($L$34:$U$34) -> 4631.3197
A36: Snitt 5 år (4 500 kWh) | Q36: =+AVERAGE($Q$34:$U$34) -> 4466.2739 | R36: =+AVERAGE($Q$34:$U$34) -> 4466.2739 | S36: =+AVERAGE($Q$34:$U$34) -> 4466.2739 | T36: =+AVERAGE($Q$34:$U$34) -> 4466.2739 | U36: =+AVERAGE($Q$34:$U$34) -> 4466.2739
A37: Snitt 3 år (4 300) | S37: =+AVERAGE($S$34:$U$34) -> 4277.8977 | T37: =+AVERAGE($S$34:$U$34) -> 4277.8977 | U37: =+AVERAGE($S$34:$U$34) -> 4277.8977

Sheet Bio
A1: 09703: Energibalansen. Vedforbruk i boliger, etter statistikkvariabel, region, fyringsteknologi og år
A3: Antatte virkningsgrader: Åpen peis ca 15 % (varierer), gammel teknologi 50 %, ny teknologi 75 %
C4: 2005 | D4: 2006 | E4: 2007 | F4: 2008 | G4: 2009 | H4: 2010 | I4: 2011 | J4: 2012 | K4: 2013 | L4: 2014 | M4: 2015 | N4: 2016 | O4: 2017 | P4: 2018 | Q4: 2019 | R4: 2020 | S4: 2021 | T4: 2022 | U4: 2023 | V4: 2024
A5: Ved - teoretisk energiinnhold (TWh) | B5: Åpen peis | C5: 0.22 | D5: 0.2 | E5: 0.24 | F5: 0.28 | G5: 0.23 | H5: 0.31 | I5: 0.23 | J5: 0.26 | K5: 0.21 | L5: 0.21 | M5: 0.13 | N5: 0.16 | O5: 0.14 | P5: 0.14 | Q5: 0.11 | R5: 0.11 | S5: 0.1 | T5: 0.11 | U5: 0.13 | V5: 0.09
B6: Lukket ovn ny teknologi (produsert etter 1998) | C6: 2.19 | D6: 2.44 | E6: 2.4 | F6: 2.59 | G6: 2.92 | H6: 3.38 | I6: 3.12 | J6: 3.54 | K6: 2.79 | L6: 2.4 | M6: 2.61 | N6: 2.63 | O6: 2.94 | P6: 2.85 | Q6: 2.72 | R6: 2.78 | S6: 3.53 | T6: 3.66 | U6: 3.52 | V6: 3.26
B7: Lukket ovn gammel teknologi (produsert før 1998) | C7: 4.03 | D7: 3.76 | E7: 3.43 | F7: 3.12 | G7: 3.06 | H7: 3.26 | I7: 2.82 | J7: 3.02 | K7: 2.05 | L7: 1.7 | M7: 1.66 | N7: 1.45 | O7: 1.54 | P7: 1.34 | Q7: 1.08 | R7: 1.2 | S7: 1.27 | T7: 1.4 | U7: 1.41 | V7: 1.12
B8: Alle teknologier | C8: 6.44 | D8: 6.4 | E8: 6.07 | F8: 6 | G8: 6.21 | H8: 6.95 | I8: 6.18 | J8: 6.82 | K8: 5.05 | L8: 4.31 | M8: 4.4 | N8: 4.24 | O8: 4.62 | P8: 4.33 | Q8: 3.91 | R8: 4.1 | S8: 4.89 | T8: 5.18 | U8: 5.06 | V8: 4.48
A9: Temperaturkorrigert | B9: Alle teknologier | C9: =+C8*$B$32/C$32 -> 6.6802639 | D9: =+D8*$B$32/D$32 -> 6.8228882 | E9: =+E8*$B$32/E$32 -> 6.2172137 | F9: =+F8*$B$32/F$32 -> 6.238878 | G9: =+G8*$B$32/G$32 -> 6.1602715 | H9: =+H8*$B$32/H$32 -> 5.8450414 | I9: =+I8*$B$32/I$32 -> 6.5768771 | J9: =+J8*$B$32/J$32 -> 6.5671589 | ... V9: =+V8*$B$32/V$32 -> 4.8694889
A10: Ved - nyttiggjort energi (TWh) | B10: Åpen peis | C10: 0.03 | D10: 0.03 | E10: 0.04 | F10: 0.04 | G10: 0.03 | H10: 0.05 | I10: 0.04 | J10: 0.04 | K10: 0.03 | L10: 0.03 | M10: 0.02 | N10: 0.02 | O10: 0.02 | P10: 0.02 | Q10: 0.02 | R10: 0.02 | S10: 0.01 | T10: 0.02 | U10: 0.02 | V10: 0.01
B11: Lukket ovn ny teknologi (produsert etter 1998) | C11: 1.64 | D11: 1.83 | E11: 1.8 | F11: 1.95 | G11: 2.19 | H11: 2.53 | I11: 2.34 | J11: 2.65 | K11: 2.09 | L11: 1.8 | M11: 1.95 | N11: 1.97 | O11: 2.2 | P11: 2.14 | Q11: 2.04 | R11: 2.09 | S11: 2.65 | T11: 2.75 | U11: 2.64 | V11: 2.45
B12: Lukket ovn gammel teknologi (produsert før 1998) | C12: 2.02 | D12: 1.88 | E12: 1.71 | F12: 1.56 | G12: 1.53 | H12: 1.63 | I12: 1.41 | J12: 1.51 | K12: 1.02 | L12: 0.85 | M12: 0.83 | N12: 0.73 | O12: 0.77 | P12: 0.67 | Q12: 0.54 | R12: 0.6 | S12: 0.63 | T12: 0.7 | U12: 0.71 | V12: 0.56
B13: Alle teknologier | C13: 3.69 | D13: 3.74 | E13: 3.55 | F13: 3.55 | G13: 3.76 | H13: 4.21 | I13: 3.79 | J13: 4.2 | K13: 3.15 | L13: 2.68 | M13: 2.8 | N13: 2.72 | O13: 2.99 | P13: 2.83 | Q13: 2.6 | R13: 2.71 | S13: 3.29 | T13: 3.47 | U13: 3.37 | V13: 3.02
A14: Ved (1 000 tonn) | B14: Åpen peis | C14: 47.7 | D14: 43.3 | E14: 52.1 | F14: 60.5 | G14: 48.2 | H14: 66.5 | I14: 50.2 | J14: 55.8 | K14: 44.6 | L14: 45.2 | M14: 27.8 | N14: 33.9 | O14: 31 | P14: 29.5 | Q14: 22.5 | R14: 23.4 | S14: 20.8 | T14: 23.7 | U14: 26.9 | V14: 21.3
B15: Lukket ovn ny teknologi (produsert etter 1998) | C15: 467.9 | D15: 522.2 | E15: 514.4 | F15: 555.6 | G15: 625.9 | H15: 723 | I15: 669.1 | J15: 757.6 | K15: 598.1 | L15: 514.5 | M15: 557.9 | N15: 562.4 | O15: 628.8 | P15: 610.6 | Q15: 582.7 | R15: 596.1 | S15: 755.5 | T15: 784.1 | U15: 753.9 | V15: 758
B16: Lukket ovn gammel teknologi (produsert før 1998) | C16: 863.6 | D16: 805.8 | E16: 734.2 | F16: 668.3 | G16: 654.8 | H16: 698.4 | I16: 604.4 | J16: 647.4 | K16: 438.3 | L16: 363.2 | M16: 355.4 | N16: 311.1 | O16: 329.4 | P16: 287.5 | Q16: 231.3 | R16: 257.8 | S16: 270.9 | T16: 300.6 | U16: 302.9 | V16: 261.4
B17: Alle teknologier | C17: 1379.1 | D17: 1371.3 | E17: 1300.6 | F17: 1284.3 | G17: 1328.8 | H17: 1487.9 | I17: 1323.6 | J17: 1460.7 | K17: 1081 | L17: 922.9 | M17: 941.1 | N17: 907.4 | O17: 989.2 | P17: 927.6 | Q17: 836.5 | R17: 877.2 | S17: 1047.3 | T17: 1108.4 | U17: 1083.6 | V17: 1040.7
A18: Husholdninger som fyrer med ved (1 000 husholdninger) | B18: Åpen peis | C18: 117.2 | D18: 106.4 | E18: 125.6 | F18: 128.6 | G18: 103.4 | H18: 120.5 | I18: 115.7 | J18: =+AVERAGE(I18,K18) -> 108.8 | K18: 101.9 | L18: 108.6 | M18: 78 | N18: 90.8 | O18: 80 | P18: 74.5 | Q18: 59 | R18: 63.9 | S18: 53.7 | T18: 65.7 | U18: 55.2 | V18: 50.5
B19: Lukket ovn ny teknologi (produsert etter 1998) | C19: 395.2 | D19: 448.8 | E19: 464 | F19: 502.7 | G19: 555.6 | H19: 600.2 | I19: 630.2 | J19: =+AVERAGE(I19,K19) -> 645.8 | K19: 661.4 | L19: 668.9 | M19: 708.7 | N19: 731.9 | O19: 796.1 | P19: 760 | Q19: 760.4 | R19: 782 | S19: 885.2 | T19: 870.8 | U19: 884.5 | V19: 935.4
B20: Lukket ovn gammel teknologi (produsert før 1998) | C20: 705.2 | D20: 688.5 | E20: 650.6 | F20: 625.4 | G20: 599.1 | H20: 572.7 | I20: 592.8 | J20: =+AVERAGE(I20,K20) -> 547.05 | K20: 501.3 | L20: 455.1 | M20: 411.1 | N20: 406.2 | O20: 399.7 | P20: 359.4 | Q20: 316.3 | R20: 335.3 | S20: 332.3 | T20: 339.2 | U20: 329.7 | V20: 330.9
B21: Alle teknologier | C21: 1217.6 | D21: 1243.7 | E21: 1240.2 | F21: 1256.7 | G21: 1258.1 | H21: 1293.4 | I21: 1338.7 | J21: =+AVERAGE(I21,K21) -> 1301.6 | K21: 1264.5 | L21: 1232.5 | M21: 1197.8 | N21: 1228.9 | O21: 1275.8 | P21: 1193.9 | Q21: 1135.7 | R21: 1181.2 | S21: 1271.3 | T21: 1275.7 | U21: 1269.4 | V21: 1316.8
C22: =+AVERAGE($C$21:$V$21) -> 1249.675 | D22: =+AVERAGE($C$21:$V$21) -> 1249.675 | E22: =+AVERAGE($C$21:$V$21) -> 1249.675 | F22: =+AVERAGE($C$21:$V$21) -> 1249.675 | G22: =+AVERAGE($C$21:$V$21) -> 1249.675 | H22: =+AVERAGE($C$21:$V$21) -> 1249.675 | I22: =+AVERAGE($C$21:$V$21) -> 1249.675 | J22: =+AVERAGE($C$21:$V$21) -> 1249.675 | ... V22: =+AVERAGE($C$21:$V$21) -> 1249.675
B23: Andel boliger som har vedovn (alle teknologier) | D23: =+D21*1000/D49 -> 0.56154815 | E23: =+E21*1000/E49 -> 0.55300624 | F23: =+F21*1000/F49 -> 0.55255056 | G23: =+G21*1000/G49 -> 0.5468243 | H23: =+H21*1000/H49 -> 0.55655841 | I23: =+I21*1000/I49 -> 0.57135906 | J23: =+AVERAGE(I23,K23) -> 0.54919675 | K23: =+K21*1000/K49 -> 0.52703443 | L23: =+L21*1000/L49 -> 0.50787735 | M23: =+M21*1000/M49 -> 0.48764322 | N23: =+N21*1000/N49 -> 0.49445692 | O23: =+O21*1000/O49 -> 0.50715757 | P23: =+P21*1000/P49 -> 0.46861287 | Q23: =+Q21*1000/Q49 -> 0.43999682 | R23: =+R21*1000/R49 -> 0.45256011 | ... V23: =+V21*1000/V49 -> 0.48396072
A24: Ved - teoretisk energiinnhold pr bolig med teknologien (kWh/bolig) | B24: Åpen peis | C24: =+C5*1000000/C18 -> 1877.1331 | D24: =+D5*1000000/D18 -> 1879.6992 | E24: =+E5*1000000/E18 -> 1910.828 | F24: =+F5*1000000/F18 -> 2177.2939 | G24: =+G5*1000000/G18 -> 2224.3714 | H24: =+H5*1000000/H18 -> 2572.6141 | I24: =+I5*1000000/I18 -> 1987.8997 | K24: =+K5*1000000/K18 -> 2060.844 | L24: =+L5*1000000/L18 -> 1933.7017 | M24: =+M5*1000000/M18 -> 1666.6667 | N24: =+N5*1000000/N18 -> 1762.1145 | O24: =+O5*1000000/O18 -> 1750 | P24: =+P5*1000000/P18 -> 1879.1946 | Q24: =+Q5*1000000/Q18 -> 1864.4068 | R24: =+R5*1000000/R18 -> 1721.4397 | ... V24: =+V5*1000000/V18 -> 1782.1782
B25: Lukket ovn ny teknologi (produsert etter 1998) | C25: =+C6*1000000/C19 -> 5541.498 | D25: =+D6*1000000/D19 -> 5436.7201 | E25: =+E6*1000000/E19 -> 5172.4138 | F25: =+F6*1000000/F19 -> 5152.1782 | G25: =+G6*1000000/G19 -> 5255.5796 | H25: =+H6*1000000/H19 -> 5631.4562 | I25: =+I6*1000000/I19 -> 4950.8093 | K25: =+K6*1000000/K19 -> 4218.3248 | L25: =+L6*1000000/L19 -> 3587.9803 | M25: =+M6*1000000/M19 -> 3682.7995 | N25: =+N6*1000000/N19 -> 3593.3871 | O25: =+O6*1000000/O19 -> 3693.0034 | P25: =+P6*1000000/P19 -> 3750 | Q25: =+Q6*1000000/Q19 -> 3577.0647 | R25: =+R6*1000000/R19 -> 3554.9872 | ... V25: =+V6*1000000/V19 -> 3485.14
B26: Lukket ovn gammel teknologi (produsert før 1998) | C26: =+C7*1000000/C20 -> 5714.6909 | D26: =+D7*1000000/D20 -> 5461.1474 | E26: =+E7*1000000/E20 -> 5272.0566 | F26: =+F7*1000000/F20 -> 4988.8072 | G26: =+G7*1000000/G20 -> 5107.6615 | H26: =+H7*1000000/H20 -> 5692.3346 | I26: =+I7*1000000/I20 -> 4757.085 | K26: =+K7*1000000/K20 -> 4089.3676 | L26: =+L7*1000000/L20 -> 3735.4428 | M26: =+M7*1000000/M20 -> 4037.947 | N26: =+N7*1000000/N20 -> 3569.6701 | O26: =+O7*1000000/O20 -> 3852.8897 | P26: =+P7*1000000/P20 -> 3728.4363 | Q26: =+Q7*1000000/Q20 -> 3414.4799 | R26: =+R7*1000000/R20 -> 3578.8846 | ... V26: =+V7*1000000/V20 -> 3384.7084
B27: Alle teknologier | C27: =+C8*1000000/C21 -> 5289.0933 | D27: =+D8*1000000/D21 -> 5145.9355 | E27: =+E8*1000000/E21 -> 4894.3719 | F27: =+F8*1000000/F21 -> 4774.4092 | G27: =+G8*1000000/G21 -> 4936.0146 | H27: =+H8*1000000/H21 -> 5373.4344 | I27: =+I8*1000000/I21 -> 4616.4189 | K27: =+K8*1000000/K21 -> 3993.6734 | L27: =+L8*1000000/L21 -> 3496.9574 | M27: =+M8*1000000/M21 -> 3673.4012 | N27: =+N8*1000000/N21 -> 3450.2401 | O27: =+O8*1000000/O21 -> 3621.2573 | P27: =+P8*1000000/P21 -> 3626.7694 | Q27: =+Q8*1000000/Q21 -> 3442.8106 | R27: =+R8*1000000/R21 -> 3471.0464 | ... V27: =+V8*1000000/V21 -> 3402.1871
A28: Ved - nyttiggjort energi pr bolig med teknologien (kWh/bolig) | B28: Åpen peis | C28: =+C10*1000000/C18 -> 255.9727 | D28: =+D10*1000000/D18 -> 281.95489 | E28: =+E10*1000000/E18 -> 318.47134 | F28: =+F10*1000000/F18 -> 311.04199 | G28: =+G10*1000000/G18 -> 290.1354 | H28: =+H10*1000000/H18 -> 414.93776 | I28: =+I10*1000000/I18 -> 345.72169 | K28: =+K10*1000000/K18 -> 294.40628 | L28: =+L10*1000000/L18 -> 276.24309 | M28: =+M10*1000000/M18 -> 256.41026 | N28: =+N10*1000000/N18 -> 220.26432 | O28: =+O10*1000000/O18 -> 250 | P28: =+P10*1000000/P18 -> 268.45638 | Q28: =+Q10*1000000/Q18 -> 338.98305 | R28: =+R10*1000000/R18 -> 312.98905 | ... V28: =+V10*1000000/V18 -> 198.0198
B29: Lukket ovn ny teknologi (produsert etter 1998) | C29: =+C11*1000000/C19 -> 4149.7976 | D29: =+D11*1000000/D19 -> 4077.5401 | E29: =+E11*1000000/E19 -> 3879.3103 | F29: =+F11*1000000/F19 -> 3879.0531 | G29: =+G11*1000000/G19 -> 3941.6847 | H29: =+H11*1000000/H19 -> 4215.2616 | I29: =+I11*1000000/I19 -> 3713.107 | K29: =+K11*1000000/K19 -> 3159.9637 | L29: =+L11*1000000/L19 -> 2690.9852 | M29: =+M11*1000000/M19 -> 2751.5169 | N29: =+N11*1000000/N19 -> 2691.6245 | O29: =+O11*1000000/O19 -> 2763.4719 | P29: =+P11*1000000/P19 -> 2815.7895 | Q29: =+Q11*1000000/Q19 -> 2682.7985 | R29: =+R11*1000000/R19 -> 2672.6343 | ... V29: =+V11*1000000/V19 -> 2619.2003
B30: Lukket ovn gammel teknologi (produsert før 1998) | C30: =+C12*1000000/C20 -> 2864.4356 | D30: =+D12*1000000/D20 -> 2730.5737 | E30: =+E12*1000000/E20 -> 2628.3431 | F30: =+F12*1000000/F20 -> 2494.4036 | G30: =+G12*1000000/G20 -> 2553.8307 | H30: =+H12*1000000/H20 -> 2846.1673 | I30: =+I12*1000000/I20 -> 2378.5425 | K30: =+K12*1000000/K20 -> 2034.7098 | L30: =+L12*1000000/L20 -> 1867.7214 | M30: =+M12*1000000/M20 -> 2018.9735 | N30: =+N12*1000000/N20 -> 1797.1443 | O30: =+O12*1000000/O20 -> 1926.4448 | P30: =+P12*1000000/P20 -> 1864.2181 | Q30: =+Q12*1000000/Q20 -> 1707.24 | R30: =+R12*1000000/R20 -> 1789.4423 | ... V30: =+V12*1000000/V20 -> 1692.3542
B31: Alle teknologier | C31: =+C13*1000000/C21 -> 3030.5519 | D31: =+D13*1000000/D21 -> 3007.1561 | E31: =+E13*1000000/E21 -> 2862.4415 | F31: =+F13*1000000/F21 -> 2824.8588 | G31: =+G13*1000000/G21 -> 2988.6337 | H31: =+H13*1000000/H21 -> 3254.9869 | I31: =+I13*1000000/I21 -> 2831.1048 | K31: =+K13*1000000/K21 -> 2491.1032 | L31: =+L13*1000000/L21 -> 2174.4422 | M31: =+M13*1000000/M21 -> 2337.619 | N31: =+N13*1000000/N21 -> 2213.3615 | O31: =+O13*1000000/O21 -> 2343.6275 | P31: =+P13*1000000/P21 -> 2370.3828 | Q31: =+Q13*1000000/Q21 -> 2289.337 | R31: =+R13*1000000/R21 -> 2294.277 | ... V31: =+V13*1000000/V21 -> 2293.4386
A32: Graddagstall | B32: 3733.6371 | C32: 3599.3523 | D32: 3502.2232 | E32: 3645.2306 | F32: 3590.6813 | G32: 3763.7768 | H32: 4439.4516 | I32: 3508.3334 | J32: 3877.3853 | K32: 3785.0953 | L32: 3299.1393 | M32: 3440.4366 | N32: 3601.1612 | O32: 3632.4383 | P32: 3623.672 | Q32: 3618.5232 | R32: 3244.3019 | S32: 3690.5569 | T32: 3453.6672 | U32: 3729.8913 | V32: 3435
A33: Tempkorr pr bolig med teknologien | B33: Åpen peis | C33: =+C24*$B$32/C$32 -> 1947.1653 | D33: =+D24*$B$32/D$32 -> 2003.9028 | E33: =+E24*$B$32/E$32 -> 1957.1707 | F33: =+F24*$B$32/F$32 -> 2263.9785 | G33: =+G24*$B$32/G$32 -> 2206.559 | H33: =+H24*$B$32/H$32 -> 2163.6023 | I33: =+I24*$B$32/I$32 -> 2115.5619 | J33: =+J24*$B$32/J$32 -> 0 | ... V33: =+V24*$B$32/V$32 -> 1937.1199
B34: Lukket ovn ny teknologi (produsert etter 1998) | C34: =+C25*$B$32/C$32 -> 5748.2405 | D34: =+D25*$B$32/D$32 -> 5795.9584 | E34: =+E25*$B$32/E$32 -> 5297.8586 | F34: =+F25*$B$32/F$32 -> 5357.3019 | G34: =+G25*$B$32/G$32 -> 5213.4938 | H34: =+H25*$B$32/H$32 -> 4736.1287 | I34: =+I25*$B$32/I$32 -> 5268.7482 | J34: =+J25*$B$32/J$32 -> 0 | ... V34: =+V25*$B$32/V$32 -> 3788.1363
B35: Lukket ovn gammel teknologi (produsert før 1998) | C35: =+C26*$B$32/C$32 -> 5927.8949 | D35: =+D26*$B$32/D$32 -> 5821.9997 | E35: =+E26*$B$32/E$32 -> 5399.918 | F35: =+F26*$B$32/F$32 -> 5187.4265 | G35: =+G26*$B$32/G$32 -> 5066.7603 | H35: =+H26*$B$32/H$32 -> 4787.3282 | I35: =+I26*$B$32/I$32 -> 5062.5831 | J35: =+J26*$B$32/J$32 -> 0 | ... V35: =+V26*$B$32/V$32 -> 3678.9732
B36: Alle teknologier | C36: =+C27*$B$32/C$32 -> 5486.4191 | D36: =+D27*$B$32/D$32 -> 5485.9598 | E36: =+E27*$B$32/E$32 -> 5013.0734 | F36: =+F27*$B$32/F$32 -> 4964.4927 | G36: =+G27*$B$32/G$32 -> 4896.4879 | H36: =+H27*$B$32/H$32 -> 4519.1289 | I36: =+I27*$B$32/I$32 -> 4912.8835 | K36: =+K27*$B$32/K$32 -> 3939.3796 | L36: =+L27*$B$32/L$32 -> 3957.508 | M36: =+M27*$B$32/M$32 -> 3986.4555 | N36: =+N27*$B$32/N$32 -> 3577.164 | O36: =+O27*$B$32/O$32 -> 3722.1446 | P36: =+P27*$B$32/P$32 -> 3736.8285 | Q36: =+Q27*$B$32/Q$32 -> 3552.3347 | R36: =+R27*$B$32/R$32 -> 3994.5813 | ... V36: =+V27*$B$32/V$32 -> 3697.9715
B37: Snitt 20 år (4 300) | C37: =+AVERAGE($C$36:$V$36) -> 4300.7362 | D37: =+AVERAGE($C$36:$V$36) -> 4300.7362 | E37: =+AVERAGE($C$36:$V$36) -> 4300.7362 | F37: =+AVERAGE($C$36:$V$36) -> 4300.7362 | G37: =+AVERAGE($C$36:$V$36) -> 4300.7362 | H37: =+AVERAGE($C$36:$V$36) -> 4300.7362 | I37: =+AVERAGE($C$36:$V$36) -> 4300.7362 | J37: =+AVERAGE($C$36:$V$36) -> 4300.7362 | ... V37: =+AVERAGE($C$36:$V$36) -> 4300.7362
B38: Snitt 10 år (3 900) | M38: =+AVERAGE($M$36:$V$36) -> 3853.8654 | N38: =+AVERAGE($M$36:$V$36) -> 3853.8654 | O38: =+AVERAGE($M$36:$V$36) -> 3853.8654 | P38: =+AVERAGE($M$36:$V$36) -> 3853.8654 | Q38: =+AVERAGE($M$36:$V$36) -> 3853.8654 | R38: =+AVERAGE($M$36:$V$36) -> 3853.8654 | S38: =+AVERAGE($M$36:$V$36) -> 3853.8654 | T38: =+AVERAGE($M$36:$V$36) -> 3853.8654 | ... V38: =+AVERAGE($M$36:$V$36) -> 3853.8654
B39: Snitt 5 år (4000) | R39: =+AVERAGE($R$36:$V$36) -> 3992.7454 | S39: =+AVERAGE($R$36:$V$36) -> 3992.7454 | T39: =+AVERAGE($R$36:$V$36) -> 3992.7454 | U39: =+AVERAGE($R$36:$V$36) -> 3992.7454 | V39: =+AVERAGE($R$36:$V$36) -> 3992.7454
A42: 06265: Boliger, etter statistikkvariabel, region, bygningstype og år | D42: 2006 | E42: 2007 | F42: 2008 | G42: 2009 | H42: 2010 | I42: 2011 | J42: 2012 | K42: 2013 | L42: 2014 | M42: 2015 | N42: 2016 | O42: 2017 | P42: 2018 | Q42: 2019 | R42: 2020 | S42: 2021 | T42: 2022 | U42: 2023 | V42: 2024
B43: Enebolig | D43: 1200816 | E43: 1205121 | F43: 1207665 | G43: 1211431 | H43: 1219903 | I43: 1223485 | J43: 1230074 | K43: 1237287 | L43: 1244431 | M43: 1251315 | N43: 1258298 | O43: 1265093 | P43: 1271158 | Q43: 1276690 | R43: 1281004 | S43: 1285146 | T43: 1290003 | U43: 1294931 | V43: 1299428
...

Sheet VP
C3: Varmeproduksjon husholdninger, GWh
B4: År | C4: Luft/ luft | D4: Luft/ vann | E4: Væske/ vann | F4: Ventilasjonsluft | G4: VRF / VRV | H4: SUM
B5: 2005 | C5: 1368.1011 | D5: 31.213934 | E5: 216.62553 | F5: 45.298458 | G5: 0 | H5: =+SUM(C5:G5) -> 1661.239
B6: 2006 | C6: 2029.0532 | D6: 53.562877 | E6: 255.57581 | F6: 46.515295 | G6: 0 | H6: =+SUM(C6:G6) -> 2384.7072
B7: 2007 | C7: 2613.5597 | D7: 84.956766 | E7: 297.20256 | F7: 50.376718 | G7: 0 | H7: =+SUM(C7:G7) -> 3046.0957
B8: 2008 | C8: 3300.6611 | D8: 122.77791 | E8: 351.50362 | F8: 52.860027 | G8: 0 | H8: =+SUM(C8:G8) -> 3827.8027
B9: 2009 | C9: 3965.7696 | D9: 160.99245 | E9: 403.36227 | F9: 54.587294 | G9: 0 | H9: =+SUM(C9:G9) -> 4584.7116
B10: 2010 | C10: 4728.019 | D10: 193.83176 | E10: 450.35842 | F10: 53.930767 | G10: 0 | H10: =+SUM(C10:G10) -> 5426.14
B11: 2011 | C11: 5401.6353 | D11: 221.53032 | E11: 511.18069 | F11: 54.813753 | G11: 0 | H11: =+SUM(C11:G11) -> 6189.16
B12: 2012 | C12: 5880.3318 | D12: 246.2271 | E12: 562.81623 | F12: 54.513584 | G12: 0 | H12: =+SUM(C12:G12) -> 6743.8887
B13: 2013 | C13: 6283.7464 | D13: 269.31825 | E13: 609.12526 | F13: 55.265511 | G13: 0 | H13: =+SUM(C13:G13) -> 7217.4555
B14: 2014 | C14: 6598.3053 | D14: 291.46903 | E14: 654.2206 | F14: 56.403081 | G14: 0 | H14: =+SUM(C14:G14) -> 7600.398
B15: 2015 | C15: 6935.1494 | D15: 312.5004 | E15: 689.51492 | F15: 61.906403 | G15: 0 | H15: =+SUM(C15:G15) -> 7999.0711
B16: 2016 | C16: 7287.3869 | D16: 331.30694 | E16: 726.45585 | F16: 68.323786 | G16: 0 | H16: =+SUM(C16:G16) -> 8413.4735
... B24: 2024 | C24: 11484.615 | D24: 422.62313 | E24: 996.53435 | F24: 112.72279 | G24: 0 | H24: =+SUM(C24:G24) -> 13016.495
B25: 2025 | C25: 11945.274 | D25: 422.6215 | E25: 1007.3519 | F25: 114.94822 | G25: 0 | H25: 13490.195
C28: Varmeproduksjon yrkesbygg, GWh
B29: År | C29: Luft/ luft | D29: Luft/vann | E29: Væske/ vann | F29: Ventilasjonsluft | G29: VRF / VRV | H29: SUM
B30: 2005 | C30: 215.65503 | D30: 77.869988 | E30: 758.25883 | F30: 146.94969 | G30: 0 | H30: 1198.7335
B31: 2006 | C31: 319.84153 | D31: 133.62432 | E31: 894.59728 | F31: 150.89715 | G31: 0 | H31: 1498.9603
B32: 2007 | C32: 411.97783 | D32: 211.94324 | E32: 1040.3043 | F32: 163.42373 | G32: 0 | H32: 1827.6491
B33: 2008 | C33: 520.28626 | D33: 306.29637 | E33: 1230.3754 | F33: 171.47966 | G33: 0 | H33: 2228.4377
B34: 2009 | C34: 625.12792 | D34: 401.6309 | E34: 1411.8973 | F34: 177.08298 | G34: 0 | H34: 2615.7391
B35: 2010 | C35: 745.282 | D35: 483.55575 | E35: 1576.3989 | F35: 174.95318 | G35: 28.215376 | H35: 3008.4052
B36: 2011 | C36: 851.46475 | D36: 552.65585 | E36: 1789.2963 | F36: 177.81762 | G36: 41.858335 | H36: 3413.0929
B37: 2012 | C37: 926.92213 | D37: 614.26739 | E37: 1970.0373 | F37: 176.84386 | G37: 47.056902 | H37: 3735.1276
B38: 2013 | C38: 990.51275 | D38: 671.8733 | E38: 2132.1338 | F38: 179.28313 | G38: 53.884999 | H38: 4027.688
B39: 2014 | C39: 1040.097 | D39: 727.13328 | E39: 2289.9819 | F39: 182.97345 | G39: 62.818982 | H39: 4303.0046
B40: 2015 | C40: 1093.194 | D40: 779.60064 | E40: 2413.5233 | F40: 200.8264 | G40: 70.004433 | H40: 4557.1488
B41: 2016 | C41: 1148.7175 | D41: 826.51766 | E41: 2542.8285 | F41: 221.64461 | G41: 75.220881 | H41: 4814.9291
... B49: 2024 | C49: 1810.3304 | D49: 1054.3259 | E49: 3488.1898 | F49: 365.67644 | G49: 75.479419 | H49: 6794.002
B50: 2025 | C50: 1882.9445 | D50: 1054.3218 | E50: 3526.0549 | F50: 372.89581 | G50: 73.659238 | H50: =+SUM(C50:G50) -> 6909.8763

Sheet FV
D2: Normalår | E2: 3733.6371
D3: Tempavhengig | E3: 0.8
A4: BOLIG | C4: FV levert til husholdning | D4: Graddagstall | E4: Tempkorr | F4: Økning
B5: 2005 | C5: 427 | D5: 3599.3523 | E5: =+C5*$E$3*$E$2/D5+C5*(1-$E$3) -> 439.74443
B6: 2006 | C6: 502 | D6: 3502.2232 | E6: =+C6*$E$3*$E$2/D6+C6*(1-$E$3) -> 528.53623 | F6: =+E6-E5 -> 88.7918
B7: 2007 | C7: 568 | D7: 3645.2306 | E7: =+C7*$E$3*$E$2/D7+C7*(1-$E$3) -> 579.02041 | F7: =+E7-E6 -> 50.484177
B8: 2008 | C8: 718 | D8: 3590.6813 | E8: =+C8*$E$3*$E$2/D8+C8*(1-$E$3) -> 740.86859 | F8: =+E8-E7 -> 161.84817
B9: 2009 | C9: 751 | D9: 3763.7768 | E9: =+C9*$E$3*$E$2/D9+C9*(1-$E$3) -> 746.1889 | F9: =+E9-E8 -> 5.3203171
B10: 2010 | C10: 1084 | D10: 4439.4516 | E10: =+C10*$E$3*$E$2/D10+C10*(1-$E$3) -> 946.1266 | F10: =+E10-E9 -> 199.9377
B11: 2011 | C11: 788 | D11: 3508.3334 | E11: =+C11*$E$3*$E$2/D11+C11*(1-$E$3) -> 828.48403 | F11: =+E11-E10 -> -117.64257
B12: 2012 | C12: 950 | D12: 3877.3853 | E12: =+C12*$E$3*$E$2/D12+C12*(1-$E$3) -> 921.82416 | F12: =+E12-E11 -> 93.34013
B13: 2013 | C13: 1083 | D13: 3785.0953 | E13: =+C13*$E$3*$E$2/D13+C13*(1-$E$3) -> 1071.2213 | F13: =+E13-E12 -> 149.39718
B14: 2014 | C14: 1000 | D14: 3299.1393 | E14: =+C14*$E$3*$E$2/D14+C14*(1-$E$3) -> 1105.3603 | F14: =+E14-E13 -> 34.138944
B15: 2015 | C15: 1037 | D15: 3440.4366 | E15: =+C15*$E$3*$E$2/D15+C15*(1-$E$3) -> 1107.7001 | F15: =+E15-E14 -> 2.3398057
B16: 2016 | C16: 1212 | D16: 3601.1612 | E16: =+C16*$E$3*$E$2/D16+C16*(1-$E$3) -> 1247.6687 | F16: =+E16-E15 -> 139.96857
B17: 2017 | C17: 1365 | D17: 3632.4383 | E17: =+C17*$E$3*$E$2/D17+C17*(1-$E$3) -> 1395.4228 | F17: =+E17-E16 -> 147.75417
... B23: 2023 | C23: 1925 | D23: 3729.8913 | E23: =+C23*$E$3*$E$2/D23+C23*(1-$E$3) -> 1926.5466 | F23: =+E23-E22 -> 167.41168
B24: 2024 | C24: 1855 | D24: 3435 | E24: =+C24*$E$3*$E$2/D24+C24*(1-$E$3) -> 1984.0182 | F24: =+E24-E23 -> 57.471634
C27: Boliger i boligblokk | D27: Økning | H27: Temperaturkorrigert | I27: Snitt 10 år | J27: Snitt 5 år
B28: 2005 | G28: 2005 | H28: =+E5 -> 439.74443
B29: 2006 | C29: 463172 | G29: 2006 | H29: =+E6 -> 528.53623
B30: 2007 | C30: 478293 | D30: =+C30-C29 -> 15121 | G30: 2007 | H30: =+E7 -> 579.02041
B31: 2008 | C31: 498592 | D31: =+C31-C30 -> 20299 | G31: 2008 | H31: =+E8 -> 740.86859
B32: 2009 | C32: 514481 | D32: =+C32-C31 -> 15889 | G32: 2009 | H32: =+E9 -> 746.1889
B33: 2010 | C33: 522992 | D33: =+C33-C32 -> 8511 | G33: 2010 | H33: =+E10 -> 946.1266
B34: 2011 | C34: 529453 | D34: =+C34-C33 -> 6461 | G34: 2011 | H34: =+E11 -> 828.48403
B35: 2012 | C35: 535509 | D35: =+C35-C34 -> 6056 | G35: 2012 | H35: =+E12 -> 921.82416
B36: 2013 | C36: 548358 | D36: =+C36-C35 -> 12849 | G36: 2013 | H36: =+E13 -> 1071.2213
B37: 2014 | C37: 560173 | D37: =+C37-C36 -> 11815 | G37: 2014 | H37: =+E14 -> 1105.3603 | I37: =+AVERAGE($H$38:$H$47) -> 1582.6108
B38: 2015 | C38: 572914 | D38: =+C38-C37 -> 12741 | G38: 2015 | H38: =+E15 -> 1107.7001 | I38: =+AVERAGE($H$38:$H$47) -> 1582.6108
B39: 2016 | C39: 585679 | D39: =+C39-C38 -> 12765 | G39: 2016 | H39: =+E16 -> 1247.6687 | I39: =+AVERAGE($H$38:$H$47) -> 1582.6108
B40: 2017 | C40: 598020 | D40: =+C40-C39 -> 12341 | G40: 2017 | H40: =+E17 -> 1395.4228 | I40: =+AVERAGE($H$38:$H$47) -> 1582.6108
B41: 2018 | C41: 610742 | D41: =+C41-C40 -> 12722 | G41: 2018 | H41: =+E18 -> 1442.1821 | I41: =+AVERAGE($H$38:$H$47) -> 1582.6108
B42: 2019 | C42: 628145 | D42: =+C42-C41 -> 17403 | G42: 2019 | H42: =+E19 -> 1587.3965 | I42: =+AVERAGE($H$38:$H$47) -> 1582.6108 | J42: =+AVERAGE($H$43:$H$47) -> 1809.1475
B43: 2020 | C43: 643631 | D43: =+C43-C42 -> 15486 | G43: 2020 | H43: =+E20 -> 1644.0131 | I43: =+AVERAGE($H$38:$H$47) -> 1582.6108 | J43: =+AVERAGE($H$43:$H$47) -> 1809.1475
B44: 2021 | C44: 655867 | D44: =+C44-C43 -> 12236 | G44: 2021 | H44: =+E21 -> 1732.0248 | I44: =+AVERAGE($H$38:$H$47) -> 1582.6108 | J44: =+AVERAGE($H$43:$H$47) -> 1809.1475
B45: 2022 | C45: 671124 | D45: =+C45-C44 -> 15257 | G45: 2022 | H45: =+E22 -> 1759.1349 | I45: =+AVERAGE($H$38:$H$47) -> 1582.6108 | J45: =+AVERAGE($H$43:$H$47) -> 1809.1475
B46: 2023 | C46: 686238 | D46: =+C46-C45 -> 15114 | G46: 2023 | H46: =+E23 -> 1926.5466 | I46: =+AVERAGE($H$38:$H$47) -> 1582.6108 | J46: =+AVERAGE($H$43:$H$47) -> 1809.1475
B47: 2024 | C47: 702866 | D47: =+C47-C46 -> 16628 | G47: 2024 | H47: =+E24 -> 1984.0182 | I47: =+AVERAGE($H$38:$H$47) -> 1582.6108 | J47: =+AVERAGE($H$43:$H$47) -> 1809.1475
D51: Normalår | E51: 3733.6371
...

Sheet Boligbygging
A1: 05940: Boligbygg, etter statistikkvariabel, bygningstype og år
B3: Fullførte boliger | C3: 2005 | D3: 2006 | E3: 2007 | F3: 2008 | G3: 2009 | H3: 2010 | I3: 2011 | J3: 2012 | K3: 2013 | L3: 2014 | M3: 2015 | N3: 2016 | O3: 2017 | P3: 2018 | Q3: 2019 | R3: 2020 | S3: 2021 | T3: 2022 | U3: 2023
B4: 111 Enebolig | C4: 5303 | D4: 5022 | E4: 5488 | F4: 5721 | G4: 5420 | H4: 4968 | I4: 5673 | J4: 5997 | K4: 5981 | L4: 5989 | M4: 5941 | N4: 6136 | O4: 5742 | P4: 5235 | Q4: 5099 | R4: 5005 | S4: 4858 | T4: 5062 | U4: 4286
B5: 112 Enebolig med hybelleilighet, sokkelleilighet o.l. | C5: 2161 | D5: 1897 | E5: 1675 | F5: 1762 | G5: 1510 | H5: 1409 | I5: 1358 | J5: 1547 | K5: 1497 | L5: 1701 | M5: 1775 | N5: 1751 | O5: 1611 | P5: 1466 | Q5: 1193 | R5: 1220 | S5: 1059 | T5: 1033 | U5: 891
B6: 113 Våningshus | C6: 223 | D6: 202 | E6: 200 | F6: 176 | G6: 165 | H6: 164 | I6: 179 | J6: 165 | K6: 187 | L6: 178 | M6: 219 | N6: 216 | O6: 192 | P6: 168 | Q6: 164 | R6: 181 | S6: 141 | T6: 161 | U6: 147
B7: 121 Del av tomannsbolig, vertikaldelt | C7: 2003 | D7: 2059 | E7: 2067 | F7: 2006 | G7: 1508 | H7: 1523 | I7: 1713 | J7: 1931 | K7: 2044 | L7: 2093 | M7: 2082 | N7: 2281 | O7: 2385 | P7: 2132 | Q7: 2058 | R7: 2028 | S7: 1942 | T7: 1981 | U7: 1699
B8: 122 Tomannsbolig, horisontaldelt | C8: 417 | D8: 457 | E8: 412 | F8: 499 | G8: 469 | H8: 361 | I8: 358 | J8: 366 | K8: 462 | L8: 339 | M8: 424 | N8: 422 | O8: 456 | P8: 595 | Q8: 385 | R8: 343 | S8: 364 | T8: 251 | U8: 257
B9: 123 Del av våninghus tomannsbustad, vertikaltdelt | C9: 28 | D9: 22 | E9: 22 | F9: 11 | G9: 17 | H9: 13 | I9: 12 | J9: 16 | K9: 18 | L9: 20 | M9: 7 | N9: 18 | O9: 23 | P9: 16 | Q9: 10 | R9: 14 | S9: 8 | T9: 10 | U9: 13
B10: 124 Våningshus tomannsbolig, horisontaltdelt | C10: 15 | D10: 15 | E10: 16 | F10: 10 | G10: 16 | H10: 9 | I10: 12 | J10: 12 | K10: 9 | L10: 16 | M10: 11 | N10: 19 | O10: 10 | P10: 13 | Q10: 5 | R10: 6 | S10: 4 | T10: 0 | U10: 3
B11: 131 Rekkehus | C11: 1886 | D11: 1301 | E11: 1680 | F11: 1300 | G11: 984 | H11: 841 | I11: 1279 | J11: 1787 | K11: 1669 | L11: 1685 | M11: 1598 | N11: 1780 | O11: 1814 | P11: 1893 | Q11: 1807 | R11: 1533 | S11: 1546 | T11: 1807 | U11: 1661
B12: 133 Kjedehus inkl.atriumhus | C12: 276 | D12: 323 | E12: 320 | F12: 239 | G12: 150 | H12: 253 | I12: 328 | J12: 531 | K12: 419 | L12: 380 | M12: 389 | N12: 436 | O12: 547 | P12: 638 | Q12: 531 | R12: 501 | S12: 499 | T12: 495 | U12: 342
B13: 135 Terrassehus | C13: 207 | D13: 147 | E13: 168 | F13: 148 | G13: 108 | H13: 106 | I13: 69 | J13: 153 | K13: 138 | L13: 61 | M13: 25 | N13: 16 | O13: 54 | P13: 32 | Q13: 45 | R13: 18 | S13: 20 | T13: 23 | U13: 123
B14: 136 Andre småhus med 3 boliger eller flere | C14: 2499 | D14: 2344 | E14: 2237 | F14: 1886 | G14: 1294 | H14: 1286 | I14: 1617 | J14: 1470 | K14: 1680 | L14: 1716 | M14: 1796 | N14: 2115 | O14: 2428 | P14: 2217 | Q14: 1740 | R14: 1669 | S14: 1540 | T14: 1421 | U14: 1341
B15: 141 Store frittliggende boligbygg på 2 etasjer | C15: 1973 | D15: 1431 | E15: 2242 | F15: 1525 | G15: 694 | H15: 738 | I15: 733 | J15: 1222 | K15: 894 | L15: 1073 | M15: 1078 | N15: 1407 | O15: 1262 | P15: 1153 | Q15: 1122 | R15: 984 | S15: 834 | T15: 978 | U15: 875
... B24: 000 Andre bygg enn boligbygg | C24: 691 | D24: 810 | E24: 876 | F24: 780 | G24: 784 | H24: 802 | I24: 372 | J24: 791 | K24: 763 | L24: 1040 | M24: 831 | N24: 607 | O24: 1092 | P24: 822 | Q24: 725 | R24: 869 | S24: 395 | T24: 547 | U24: 466
B25: SMÅHUS | C25: =+C4+C5+C6+C7+C8+C9+C10+C11+C12+C13+C14 -> 15018 | D25: =+D4+D5+D6+D7+D8+D9+D10+D11+D12+D13+D14 -> 13789 | E25: =+E4+E5+E6+E7+E8+E9+E10+E11+E12+E13+E14 -> 14285 | F25: =+F4+F5+F6+F7+F8+F9+F10+F11+F12+F13+F14 -> 13758 | G25: =+G4+G5+G6+G7+G8+G9+G10+G11+G12+G13+G14 -> 11641 | H25: =+H4+H5+H6+H7+H8+H9+H10+H11+H12+H13+H14 -> 10933 | I25: =+I4+I5+I6+I7+I8+I9+I10+I11+I12+I13+I14 -> 12598 | J25: =+J4+J5+J6+J7+J8+J9+J10+J11+J12+J13+J14 -> 13975 | ... U25: =+U4+U5+U6+U7+U8+U9+U10+U11+U12+U13+U14 -> 10763
B26: "Boligblokk" | C26: =+SUM(C15:C20) -> 12708 | D26: =+SUM(D15:D20) -> 13647 | E26: =+SUM(E15:E20) -> 15392 | F26: =+SUM(F15:F20) -> 13714 | G26: =+SUM(G15:G20) -> 8694 | H26: =+SUM(H15:H20) -> 5313 | I26: =+SUM(I15:I20) -> 5659 | J26: =+SUM(J15:J20) -> 10550 | ... U26: =+SUM(U15:U20) -> 16343
A29: 06265: Boliger, etter statistikkvariabel, bygningstype og år
D31: 2006 | E31: 2007 | F31: 2008 | G31: 2009 | H31: 2010 | I31: 2011 | J31: 2012 | K31: 2013 | L31: 2014 | M31: 2015 | N31: 2016 | O31: 2017 | P31: 2018 | Q31: 2019 | R31: 2020 | S31: 2021 | T31: 2022 | U31: 2023 | V31: 2024
A32: Boliger (bebodde og ubebodde) | B32: Enebolig | D32: 1200816 | E32: 1205121 | F32: 1207665 | G32: 1211431 | H32: 1219903 | I32: 1223485 | J32: 1230074 | K32: 1237287 | L32: 1244431 | M32: 1251315 | N32: 1258298 | O32: 1265093 | P32: 1271158 | Q32: 1276690 | R32: 1281004 | S32: 1285146 | T32: 1290003 | U32: 1294931 | V32: 1299428
B33: Tomannsbolig | D33: 202725 | E33: 205388 | F33: 207742 | G33: 209873 | H33: 211596 | I33: 213937 | J33: 216059 | K33: 218266 | L33: 220265 | M33: 222702 | N33: 225132 | O33: 227798 | P33: 230328 | Q33: 232948 | R33: 235467 | S33: 237818 | T33: 239395 | U33: 241155 | V33: 242593
B34: Rekkehus, kjedehus og andre småhus | D34: 250583 | E34: 255063 | F34: 260315 | G34: 264304 | H34: 267821 | I34: 271304 | J34: 275801 | K34: 281154 | L34: 285141 | M34: 288822 | N34: 292926 | O34: 297409 | P34: 302720 | Q34: 307910 | R34: 311648 | S34: 315511 | T34: 319652 | U34: 324010 | V34: 327623
B35: Boligblokk | D35: 463172 | E35: 478293 | F35: 498592 | G35: 514481 | H35: 522992 | I35: 529453 | J35: 535509 | K35: 548358 | L35: 560173 | M35: 572914 | N35: 585679 | O35: 598020 | P35: 610742 | Q35: 628145 | R35: 643631 | S35: 655867 | T35: 671124 | U35: 686238 | V35: 702866
B36: Bygning for bofellesskap | D36: 37367 | E36: 38694 | F36: 40011 | G36: 40995 | H36: 41195 | I36: 43136 | J36: 44753 | K36: 45974 | L36: 49010 | M36: 51334 | N36: 53227 | O36: 55580 | P36: 60458 | Q36: 61912 | R36: 63309 | S36: 68479 | T36: 70194 | U36: 72108 | V36: 72572
B37: Andre bygningstyper | D37: 60107 | E37: 60092 | F37: 60037 | G37: 59655 | H37: 60418 | I37: 61695 | J37: 66566 | K37: 68235 | L37: 67747 | M37: 69217 | N37: 70091 | O37: 71689 | P37: 72326 | Q37: 73550 | R37: 74981 | S37: 75017 | T37: 76139 | U37: 75859 | V37: 75800
B38: Totalt | D38: =+SUM(D32:D37) -> 2214770 | E38: =+SUM(E32:E37) -> 2242651 | F38: =+SUM(F32:F37) -> 2274362 | G38: =+SUM(G32:G37) -> 2300739 | H38: =+SUM(H32:H37) -> 2323925 | I38: =+SUM(I32:I37) -> 2343010 | J38: =+SUM(J32:J37) -> 2368762 | K38: =+SUM(K32:K37) -> 2399274 | ... V38: =+SUM(V32:V37) -> 2720882
B40: Økning boligblokk | E40: =+E35-D35 -> 15121 | F40: =+F35-E35 -> 20299 | G40: =+G35-F35 -> 15889 | H40: =+H35-G35 -> 8511 | I40: =+I35-H35 -> 6461 | J40: =+J35-I35 -> 6056 | K40: =+K35-J35 -> 12849 | L40: =+L35-K35 -> 11815 | ... V40: =+V35-U35 -> 16628
A47: Måleenhet:
A48: Fullførte boliger:
A49: boliger
A50: Målemetode:
A51: Fullførte boliger:
A52: Forløp (periodesum)
A54: Referansetid:
A55: Fullførte boliger
A56: 31.12.
A62: Offisiell statistikk
A64: Database:
A65: Ekstern PRODUKSJON
... A68: Fullforte
